Workbook

Sheet Costeo
A1: Costeo del menú de comida — costo por plato y margen · La Quinta Pata
A2: Food menu costing. Edite precios en la columna D (azul). El costo viene de Especificaciones → Insumos → Preparaciones. Estado marca platos >3 pts sobre el objetivo.
A4: Plato | B4: Dish (EN) | C4: Sección | D4: Precio menú ($) | E4: Precio neto sin ITBMS ($) | F4: Costo ($) | G4: Costo % | H4: Objetivo % | I4: Ganancia bruta ($) | J4: Precio para objetivo ($, redondeo 0.50) | K4: Estado
A5: Chicharroncitos del burro | B5: Pork cracklings | C5: Entradas | D5: 13 | E5: =IF(Ajustes!$B$12=1,D5/(1+Ajustes!$B$13),D5) -> 12.149533 | F5: =SUMIF(Especificaciones!$A$5:$A$109,A5,Especificaciones!$G$5:$G$109) -> 4.85625 | G5: =IFERROR(F5/E5,0) -> 0.39970673 | H5: =IFERROR(INDEX(Ajustes!$B$17:$B$20,MATCH(C5,Ajustes!$A$17:$A$20,0)),0.3) -> 0.28 | I5: =E5-F5 -> 7.2932827 | J5: =IFERROR(CEILING(F5/H5*IF(Ajustes!$B$12=1,1+Ajustes!$B$13,1),0.5),0) -> 19 | K5: =IF(G5>H5+0.03,"Reajustar precio / porción",IF(G5<H5-0.1,"Margen alto","OK")) -> Reajustar precio / porción
A6: Mini sliders Angus (3 unid) | B6: Angus sliders (3) | C6: Entradas | D6: 10 | E6: =IF(Ajustes!$B$12=1,D6/(1+Ajustes!$B$13),D6) -> 9.3457944 | F6: =SUMIF(Especificaciones!$A$5:$A$109,A6,Especificaciones!$G$5:$G$109) -> 4.4911765 | G6: =IFERROR(F6/E6,0) -> 0.48055588 | H6: =IFERROR(INDEX(Ajustes!$B$17:$B$20,MATCH(C6,Ajustes!$A$17:$A$20,0)),0.3) -> 0.28 | I6: =E6-F6 -> 4.8546179 | J6: =IFERROR(CEILING(F6/H6*IF(Ajustes!$B$12=1,1+Ajustes!$B$13,1),0.5),0) -> 17.5 | K6: =IF(G6>H6+0.03,"Reajustar precio / porción",IF(G6<H6-0.1,"Margen alto","OK")) -> Reajustar precio / porción
A7: Nachos de carne | B7: Beef nachos | C7: Entradas | D7: 15 | E7: =IF(Ajustes!$B$12=1,D7/(1+Ajustes!$B$13),D7) -> 14.018692 | F7: =SUMIF(Especificaciones!$A$5:$A$109,A7,Especificaciones!$G$5:$G$109) -> 4.45125 | G7: =IFERROR(F7/E7,0) -> 0.3175225 | H7: =IFERROR(INDEX(Ajustes!$B$17:$B$20,MATCH(C7,Ajustes!$A$17:$A$20,0)),0.3) -> 0.28 | I7: =E7-F7 -> 9.5674416 | J7: =IFERROR(CEILING(F7/H7*IF(Ajustes!$B$12=1,1+Ajustes!$B$13,1),0.5),0) -> 17.5 | K7: =IF(G7>H7+0.03,"Reajustar precio / porción",IF(G7<H7-0.1,"Margen alto","OK")) -> Reajustar precio / porción
A8: Nachos de pollo | B8: Chicken nachos | C8: Entradas | D8: 15 | E8: =IF(Ajustes!$B$12=1,D8/(1+Ajustes!$B$13),D8) -> 14.018692 | F8: =SUMIF(Especificaciones!$A$5:$A$109,A8,Especificaciones!$G$5:$G$109) -> 3.9304167 | G8: =IFERROR(F8/E8,0) -> 0.28036972 | H8: =IFERROR(INDEX(Ajustes!$B$17:$B$20,MATCH(C8,Ajustes!$A$17:$A$20,0)),0.3) -> 0.28 | I8: =E8-F8 -> 10.088275 | J8: =IFERROR(CEILING(F8/H8*IF(Ajustes!$B$12=1,1+Ajustes!$B$13,1),0.5),0) -> 15.5 | K8: =IF(G8>H8+0.03,"Reajustar precio / porción",IF(G8<H8-0.1,"Margen alto","OK")) -> OK
A9: Salchichas estilo alemán (2 unid) | B9: German sausages (2) | C9: Entradas | D9: 9.5 | E9: =IF(Ajustes!$B$12=1,D9/(1+Ajustes!$B$13),D9) -> 8.8785047 | F9: =SUMIF(Especificaciones!$A$5:$A$109,A9,Especificaciones!$G$5:$G$109) -> 3 | G9: =IFERROR(F9/E9,0) -> 0.33789474 | H9: =IFERROR(INDEX(Ajustes!$B$17:$B$20,MATCH(C9,Ajustes!$A$17:$A$20,0)),0.3) -> 0.28 | I9: =E9-F9 -> 5.8785047 | J9: =IFERROR(CEILING(F9/H9*IF(Ajustes!$B$12=1,1+Ajustes!$B$13,1),0.5),0) -> 11.5 | K9: =IF(G9>H9+0.03,"Reajustar precio / porción",IF(G9<H9-0.1,"Margen alto","OK")) -> Reajustar precio / porción
A10: Arañitas | B10: Plantain arañitas | C10: Entradas | D10: 10 | E10: =IF(Ajustes!$B$12=1,D10/(1+Ajustes!$B$13),D10) -> 9.3457944 | F10: =SUMIF(Especificaciones!$A$5:$A$109,A10,Especificaciones!$G$5:$G$109) -> 1.4 | G10: =IFERROR(F10/E10,0) -> 0.1498 | H10: =IFERROR(INDEX(Ajustes!$B$17:$B$20,MATCH(C10,Ajustes!$A$17:$A$20,0)),0.3) -> 0.28 | I10: =E10-F10 -> 7.9457944 | J10: =IFERROR(CEILING(F10/H10*IF(Ajustes!$B$12=1,1+Ajustes!$B$13,1),0.5),0) -> 5.5 | K10: =IF(G10>H10+0.03,"Reajustar precio / porción",IF(G10<H10-0.1,"Margen alto","OK")) -> Margen alto
A11: Jalapeño poppers | B11: Jalapeño poppers | C11: Entradas | D11: 7 | E11: =IF(Ajustes!$B$12=1,D11/(1+Ajustes!$B$13),D11) -> 6.5420561 | F11: =SUMIF(Especificaciones!$A$5:$A$109,A11,Especificaciones!$G$5:$G$109) -> 1.775 | G11: =IFERROR(F11/E11,0) -> 0.27132143 | H11: =IFERROR(INDEX(Ajustes!$B$17:$B$20,MATCH(C11,Ajustes!$A$17:$A$20,0)),0.3) -> 0.28 | I11: =E11-F11 -> 4.7670561 | J11: =IFERROR(CEILING(F11/H11*IF(Ajustes!$B$12=1,1+Ajustes!$B$13,1),0.5),0) -> 7 | K11: =IF(G11>H11+0.03,"Reajustar precio / porción",IF(G11<H11-0.1,"Margen alto","OK")) -> OK
A12: Empanada de maíz (4 unid) | B12: Corn empanadas (4) | C12: Entradas | D12: 7 | E12: =IF(Ajustes!$B$12=1,D12/(1+Ajustes!$B$13),D12) -> 6.5420561 | F12: =SUMIF(Especificaciones!$A$5:$A$109,A12,Especificaciones!$G$5:$G$109) -> 3.0265625 | G12: =IFERROR(F12/E12,0) -> 0.4626317 | H12: =IFERROR(INDEX(Ajustes!$B$17:$B$20,MATCH(C12,Ajustes!$A$17:$A$20,0)),0.3) -> 0.28 | I12: =E12-F12 -> 3.5154936 | J12: =IFERROR(CEILING(F12/H12*IF(Ajustes!$B$12=1,1+Ajustes!$B$13,1),0.5),0) -> 12 | K12: =IF(G12>H12+0.03,"Reajustar precio / porción",IF(G12<H12-0.1,"Margen alto","OK")) -> Reajustar precio / porción
A13: Hummus | B13: Hummus | C13: Entradas | D13: 8 | E13: =IF(Ajustes!$B$12=1,D13/(1+Ajustes!$B$13),D13) -> 7.4766355 | F13: =SUMIF(Especificaciones!$A$5:$A$109,A13,Especificaciones!$G$5:$G$109) -> 1.7572041 | G13: =IFERROR(F13/E13,0) -> 0.23502605 | H13: =IFERROR(INDEX(Ajustes!$B$17:$B$20,MATCH(C13,Ajustes!$A$17:$A$20,0)),0.3) -> 0.28 | I13: =E13-F13 -> 5.7194314 | J13: =IFERROR(CEILING(F13/H13*IF(Ajustes!$B$12=1,1+Ajustes!$B$13,1),0.5),0) -> 7 | K13: =IF(G13>H13+0.03,"Reajustar precio / porción",IF(G13<H13-0.1,"Margen alto","OK")) -> OK
A14: Buffalo wings (8 unid) | B14: Buffalo wings (8) | C14: Entradas | D14: 8.5 | E14: =IF(Ajustes!$B$12=1,D14/(1+Ajustes!$B$13),D14) -> 7.9439252 | F14: =SUMIF(Especificaciones!$A$5:$A$109,A14,Especificaciones!$G$5:$G$109) -> 3.9850658 | G14: =IFERROR(F14/E14,0) -> 0.50164946 | H14: =IFERROR(INDEX(Ajustes!$B$17:$B$20,MATCH(C14,Ajustes!$A$17:$A$20,0)),0.3) -> 0.28 | I14: =E14-F14 -> 3.9588594 | J14: =IFERROR(CEILING(F14/H14*IF(Ajustes!$B$12=1,1+Ajustes!$B$13,1),0.5),0) -> 15.5 | K14: =IF(G14>H14+0.03,"Reajustar precio / porción",IF(G14<H14-0.1,"Margen alto","OK")) -> Reajustar precio / porción
A15: Ceviche de langostino | B15: Prawn ceviche | C15: Entradas | D15: 9.5 | E15: =IF(Ajustes!$B$12=1,D15/(1+Ajustes!$B$13),D15) -> 8.8785047 | F15: =SUMIF(Especificaciones!$A$5:$A$109,A15,Especificaciones!$G$5:$G$109) -> 5.0722222 | G15: =IFERROR(F15/E15,0) -> 0.5712924 | H15: =IFERROR(INDEX(Ajustes!$B$17:$B$20,MATCH(C15,Ajustes!$A$17:$A$20,0)),0.3) -> 0.28 | I15: =E15-F15 -> 3.8062825 | J15: =IFERROR(CEILING(F15/H15*IF(Ajustes!$B$12=1,1+Ajustes!$B$13,1),0.5),0) -> 19.5 | K15: =IF(G15>H15+0.03,"Reajustar precio / porción",IF(G15<H15-0.1,"Margen alto","OK")) -> Reajustar precio / porción
A16: Almejas borrachas | B16: Drunken clams | C16: Entradas | D16: 12.5 | E16: =IF(Ajustes!$B$12=1,D16/(1+Ajustes!$B$13),D16) -> 11.682243 | F16: =SUMIF(Especificaciones!$A$5:$A$109,A16,Especificaciones!$G$5:$G$109) -> 4.734 | G16: =IFERROR(F16/E16,0) -> 0.4052304 | H16: =IFERROR(INDEX(Ajustes!$B$17:$B$20,MATCH(C16,Ajustes!$A$17:$A$20,0)),0.3) -> 0.28 | I16: =E16-F16 -> 6.948243 | J16: =IFERROR(CEILING(F16/H16*IF(Ajustes!$B$12=1,1+Ajustes!$B$13,1),0.5),0) -> 18.5 | K16: =IF(G16>H16+0.03,"Reajustar precio / porción",IF(G16<H16-0.1,"Margen alto","OK")) -> Reajustar precio / porción
... A31: Totopos | B31: Tortilla chips | C31: Acompañamientos | D31: 3.5 | E31: =IF(Ajustes!$B$12=1,D31/(1+Ajustes!$B$13),D31) -> 3.271028 | F31: =SUMIF(Especificaciones!$A$5:$A$109,A31,Especificaciones!$G$5:$G$109) -> 0.75 | G31: =IFERROR(F31/E31,0) -> 0.22928571 | H31: =IFERROR(INDEX(Ajustes!$B$17:$B$20,MATCH(C31,Ajustes!$A$17:$A$20,0)),0.3) -> 0.25 | I31: =E31-F31 -> 2.521028 | J31: =IFERROR(CEILING(F31/H31*IF(Ajustes!$B$12=1,1+Ajustes!$B$13,1),0.5),0) -> 3.5 | K31: =IF(G31>H31+0.03,"Reajustar precio / porción",IF(G31<H31-0.1,"Margen alto","OK")) -> OK
A33: Promedio por sección · Average by section
A34: Sección | B34: Section (EN) | F34: Costo prom. ($) | G34: Costo % prom. | H34: Objetivo % | I34: Ganancia prom. ($)
A35: Entradas | B35: Starters | F35: =IFERROR(AVERAGEIF($C$5:$C$31,A35,$F$5:$F$31),0) -> 3.4666332 | G35: =IFERROR(AVERAGEIF($C$5:$C$31,A35,$G$5:$G$31),0) -> 0.35974132 | H35: =IFERROR(INDEX(Ajustes!$B$17:$B$20,MATCH(A35,Ajustes!$A$17:$A$20,0)),0) -> 0.28 | I35: =IFERROR(AVERAGEIF($C$5:$C$31,A35,$I$5:$I$31),0) -> 6.2745602
A36: Carnes, aves y pescados | B36: Mains | F36: =IFERROR(AVERAGEIF($C$5:$C$31,A36,$F$5:$F$31),0) -> 8.5778561 | G36: =IFERROR(AVERAGEIF($C$5:$C$31,A36,$G$5:$G$31),0) -> 0.4086159 | H36: =IFERROR(INDEX(Ajustes!$B$17:$B$20,MATCH(A36,Ajustes!$A$17:$A$20,0)),0) -> 0.35 | I36: =IFERROR(AVERAGEIF($C$5:$C$31,A36,$I$5:$I$31),0) -> 11.982892
A37: Menú kids | B37: Kids menu | F37: =IFERROR(AVERAGEIF($C$5:$C$31,A37,$F$5:$F$31),0) -> 2.0015619 | G37: =IFERROR(AVERAGEIF($C$5:$C$31,A37,$G$5:$G$31),0) -> 0.3569452 | H37: =IFERROR(INDEX(Ajustes!$B$17:$B$20,MATCH(A37,Ajustes!$A$17:$A$20,0)),0) -> 0.35 | I37: =IFERROR(AVERAGEIF($C$5:$C$31,A37,$I$5:$I$31),0) -> 3.6059148
A38: Acompañamientos | B38: Sides | F38: =IFERROR(AVERAGEIF($C$5:$C$31,A38,$F$5:$F$31),0) -> 0.80184034 | G38: =IFERROR(AVERAGEIF($C$5:$C$31,A38,$G$5:$G$31),0) -> 0.23199433 | H38: =IFERROR(INDEX(Ajustes!$B$17:$B$20,MATCH(A38,Ajustes!$A$17:$A$20,0)),0) -> 0.25 | I38: =IFERROR(AVERAGEIF($C$5:$C$31,A38,$I$5:$I$31),0) -> 2.6561036
A40: Estados: OK · Reajustar precio / porción = over target · Margen alto = well under target (confirmar receta)

Sheet Fichas técnicas
A1: Fichas técnicas de cocina — porción, receta y preparación
A2: Kitchen spec cards. La receta refleja Especificaciones; si cambia cantidades allá, actualice aquí.
A4: Plato | B4: Dish (EN) | C4: Sección | D4: Porción | E4: Receta | F4: Preparación
A5: Chicharroncitos del burro | B5: Pork cracklings | C5: Entradas | D5: 0.6 lb de panza (crudo) + 3 oz guacamole | E5: 0.6 lb Panza de cerdo 3 oz Guacamole 1 × Aceite de freír (porción) 1 × Sazón de la casa (porción) 1 × Condimentos y varios (por plato) | F5: Cocinar la panza en agua con sal, secar, freír en cubos hasta crocante, sazonar.
A6: Mini sliders Angus (3 unid) | B6: Angus sliders (3) | C6: Entradas | D6: 3 × 2.7 oz de carne | E6: 0.5 lb Carne molida Angus 3 × Mini pan de slider 3 × Queso en lámina (prensado) 1 × Condimentos y varios (por plato) | F6: Formar 3 bolitas, smash en plancha, queso al voltear, armar en pan tostado.
A7: Nachos de carne | B7: Beef nachos | C7: Entradas | D7: 8 tortillas + 5 oz carne + queso, pico y guacamole | E7: 8 × Tortilla de maíz 1 × Aceite de freír (porción) 0.3 lb Carne molida de res 3 oz Queso cheddar rallado 3 oz Pico de gallo 3 oz Guacamole | F7: Freír/hornear totopos de la casa, cubrir con carne y queso, gratinar, terminar con pico y guacamole.
A8: Nachos de pollo | B8: Chicken nachos | C8: Entradas | D8: 8 tortillas + 5 oz pollo + queso, pico y guacamole | E8: 8 × Tortilla de maíz 1 × Aceite de freír (porción) 0.35 lb Pechuga de pollo 3 oz Queso cheddar rallado 3 oz Pico de gallo 3 oz Guacamole | F8: Igual que nachos de carne, con pollo desmechado sazonado.
A9: Salchichas estilo alemán (2 unid) | B9: German sausages (2) | C9: Entradas | D9: 2 salchichas + 2 oz chucrut | E9: 2 × Salchicha alemana 2 oz Chucrut 1 × Condimentos y varios (por plato) | F9: Dorar en plancha, servir con chucrut caliente y mostaza.
A10: Arañitas | B10: Plantain arañitas | C10: Entradas | D10: 2 plátanos rallados | E10: 2 × Plátano verde 1 × Aceite de freír (porción) 1 × Sazón de la casa (porción) 1 × Condimentos y varios (por plato) | F10: Rallar plátano verde grueso, formar nidos, freír hasta dorar. CONFIRMAR RECETA REAL (¿lleva proteína?).
A11: Jalapeño poppers | B11: Jalapeño poppers | C11: Entradas | D11: 6 unidades | E11: 6 × Jalapeño 3 oz Queso crema 2 oz Empanizado 1 × Aceite de freír (porción) 1 × Condimentos y varios (por plato) | F11: Rellenar jalapeños con queso crema, empanizar y freír.
A12: Empanada de maíz (4 unid) | B12: Corn empanadas (4) | C12: Entradas | D12: 4 unidades, 1.5 oz de carne mechada c/u | E12: 8 oz Masa de maíz 6 oz Carne mechada 1 × Aceite de freír (porción) | F12: Formar con masa, rellenar con carne mechada, freír.
A13: Hummus | B13: Hummus | C13: Entradas | D13: 6 oz hummus + 2 tortillas | E13: 6 oz Hummus 2 × Tortilla de harina 0.5 oz Aceite de oliva | F13: Servir con aceite de oliva y tortilla tostada en triángulos.
A14: Buffalo wings (8 unid) | B14: Buffalo wings (8) | C14: Entradas | D14: 8 alitas (~1.25 lb crudo) | E14: 1.25 lb Alitas de pollo 3 oz Salsa buffalo 2 oz Aderezo ranch 1 × Aceite de freír (porción) | F14: Freír alitas, bañar en salsa buffalo, servir con ranch.
A15: Ceviche de langostino | B15: Prawn ceviche | C15: Entradas | D15: ~3 oz de langostino limpio | E15: 0.35 lb Langostino 4 × Limón 0.1 lb Cebolla 0.2 manojo Cilantro 1 × Condimentos y varios (por plato) | F15: Curar el langostino limpio en limón con cebolla, cilantro y ají.
... A31: Totopos | B31: Tortilla chips | C31: Acompañamientos | D31: 5 tortillas | E31: 5 × Tortilla de maíz 1 × Aceite de freír (porción) | F31: Cortar en triángulos y freír o hornear, sal.

Sheet Ajustes
A1: Costeo de cocina — Ajustes y leyenda · La Quinta Pata
A2: Kitchen costing — Settings & legend
A4: Leyenda · Legend
A5: Texto azul = dato que usted edita · Blue = input you edit
A6: Texto negro = fórmula, no sobrescribir · Black = formula, don't overwrite
A7: Texto verde = viene de otra hoja · Green = pulled from another sheet
A8: Fondo amarillo = supuesto a verificar (cotización / contador) · Yellow = assumption to verify
A9: Costo de alimentos solamente: no incluye mano de obra, gas, empaque ni desperdicio de servicio. · Food cost only.
A11: Impuesto · Tax
A12: ¿Precios del menú incluyen ITBMS? (1 = sí, 0 = no) · Menu prices include ITBMS? | B12: 1
A13: Tasa ITBMS comida en restaurante · ITBMS rate, restaurant food | B13: 0.07 | C13: Supuesto — confirme con su contador. · Assumption — confirm with your accountant.
A15: Costo objetivo por sección · Target food cost by section
A16: Sección · Section | B16: Objetivo % · Target % | C16: Nota · Note
A17: Entradas | B17: 0.28 | C17: Starters
A18: Carnes, aves y pescados | B18: 0.35 | C18: Mains · Cortes premium corren más alto · Premium cuts run higher
A19: Menú kids | B19: 0.35 | C19: Kids menu · Puede ser gancho para familias · Can be a family loss-leader
A20: Acompañamientos | B20: 0.25 | C20: Sides
A22: Acompañamiento incluido · Included side
A23: Costo promedio de un acompañamiento (se usa en platos con '1 acompañamiento') · Avg side cost | B23: =AVERAGE(Costeo!F27:F31) -> 0.80184034 | C23: Promedio de los 5 acompañamientos; cámbielo por un valor fijo si prefiere. · Average of the 5 sides.

Sheet Insumos
A1: Lista de precios de insumos de cocina — reemplace las celdas amarillas con cotizaciones de su proveedor
A2: Ingredient list. Rendimiento = % aprovechable después de limpiar/cocinar. Ejemplo: rib eye $11.00/lb con 90% de rendimiento → $12.22 por lb servida. Precios estimados, no cotizaciones.
A4: Insumo | B4: Ingredient (EN) | C4: Categoría | D4: Presentación de compra | E4: Unidades por compra | F4: Unidad | G4: Costo de compra | H4: Rendimiento % | I4: Costo por unidad utilizable
A5: Panza de cerdo | B5: Pork belly | C5: Proteína | D5: Por libra | E5: 1 | F5: lb | G5: 3.5 | H5: 0.6 | I5: =IFERROR(G5/(E5*H5),0) -> 5.8333333
A6: Carne molida Angus | B6: Angus ground beef | C6: Proteína | D6: Por libra | E6: 1 | F6: lb | G6: 5 | H6: 0.85 | I6: =IFERROR(G6/(E6*H6),0) -> 5.8823529
A7: Carne molida de res | B7: Ground beef | C7: Proteína | D7: Por libra | E7: 1 | F7: lb | G7: 4.5 | H7: 0.8 | I7: =IFERROR(G7/(E7*H7),0) -> 5.625
A8: Pechuga de pollo | B8: Chicken breast | C8: Proteína | D8: Por libra | E8: 1 | F8: lb | G8: 3 | H8: 0.9 | I8: =IFERROR(G8/(E8*H8),0) -> 3.3333333
A9: Pollo entero | B9: Whole chicken | C9: Proteína | D9: Por libra | E9: 1 | F9: lb | G9: 1.6 | H9: 1 | I9: =IFERROR(G9/(E9*H9),0) -> 1.6
A10: Alitas de pollo | B10: Chicken wings | C10: Proteína | D10: Por libra | E10: 1 | F10: lb | G10: 2.3 | H10: 0.95 | I10: =IFERROR(G10/(E10*H10),0) -> 2.4210526
A11: Salchicha alemana | B11: German sausage | C11: Proteína | D11: Paquete de 10 | E11: 10 | F11: unidad | G11: 12.5 | H11: 1 | I11: =IFERROR(G11/(E11*H11),0) -> 1.25
A12: Chorizo parrillero | B12: Grilling chorizo | C12: Proteína | D12: Paquete de 10 | E12: 10 | F12: unidad | G12: 11 | H12: 1 | I12: =IFERROR(G12/(E12*H12),0) -> 1.1
A13: Langostino | B13: Prawns | C13: Mariscos | D13: Por libra | E13: 1 | F13: lb | G13: 7 | H13: 0.6 | I13: =IFERROR(G13/(E13*H13),0) -> 11.666667
A14: Almejas | B14: Clams | C14: Mariscos | D14: Por libra | E14: 1 | F14: lb | G14: 3.5 | H14: 1 | I14: =IFERROR(G14/(E14*H14),0) -> 3.5
A15: Rib eye | B15: Rib eye | C15: Carne premium | D15: Por libra | E15: 1 | F15: lb | G15: 11 | H15: 0.9 | I15: =IFERROR(G15/(E15*H15),0) -> 12.222222
A16: Entraña | B16: Skirt steak | C16: Carne premium | D16: Por libra | E16: 1 | F16: lb | G16: 12 | H16: 0.85 | I16: =IFERROR(G16/(E16*H16),0) -> 14.117647
... A46: Condimentos y varios (por plato) | B46: Condiments & misc (per plate) | C46: Operación | D46: Lechuga, tomate, salsas de mesa, sal | E46: 1 | F46: unidad | G46: 0.2 | H46: 1 | I46: =IFERROR(G46/(E46*H46),0) -> 0.2
A47: Guacamole | B47: Guacamole | C47: Preparación de la casa | D47: Ver hoja Preparaciones | F47: oz | I47: =Preparaciones!$F$12 -> 0.21875
A48: Pico de gallo | B48: Pico de gallo | C48: Preparación de la casa | D48: Ver hoja Preparaciones | F48: oz | I48: =Preparaciones!$F$21 -> 0.1025
A49: Cebolla caramelizada balsámica | B49: Balsamic caramelized onion | C49: Preparación de la casa | D49: Ver hoja Preparaciones | F49: oz | I49: =Preparaciones!$F$29 -> 0.290625
A50: Salsa buffalo | B50: Buffalo sauce | C50: Preparación de la casa | D50: Ver hoja Preparaciones | F50: oz | I50: =Preparaciones!$F$35 -> 0.16333333
A51: Salsa al ajillo con vino blanco | B51: Garlic white-wine sauce | C51: Preparación de la casa | D51: Ver hoja Preparaciones | F51: oz | I51: =Preparaciones!$F$43 -> 0.246
A52: Carne mechada | B52: Shredded beef | C52: Preparación de la casa | D52: Ver hoja Preparaciones | F52: oz | I52: =Preparaciones!$F$52 -> 0.39609375
A53: Hummus | B53: Hummus | C53: Preparación de la casa | D53: Ver hoja Preparaciones | F53: oz | I53: =Preparaciones!$F$61 -> 0.18625
A54: Chimichurri | B54: Chimichurri | C54: Preparación de la casa | D54: Ver hoja Preparaciones | F54: oz | I54: =Preparaciones!$F$70 -> 0.15875
A55: Salsa marinera | B55: Marinara sauce | C55: Preparación de la casa | D55: Ver hoja Preparaciones | F55: oz | I55: =Preparaciones!$F$78 -> 0.12166667
A56: Acompañamiento incluido (promedio) | B56: Included side (average) | C56: Acompañamiento | D56: Ver Ajustes B23 | F56: unidad | I56: =Ajustes!$B$23 -> 0.80184034

Sheet Preparaciones
A1: Preparaciones base de cocina — costo por oz alimenta Insumos
A2: Kitchen base preps — cost per oz feeds Insumos
A4: Preparación · Prep | B4: Ingrediente | C4: Cant. · Qty | D4: Unidad | E4: Costo / unidad | F4: Costo línea | G4: Método y vida útil · Method & shelf life
A5: Guacamole | B5: Aguacate | C5: 4 | D5: unidad | E5: 1 | F5: =C5*E5 -> 4 | G5: Majar aguacate, mezclar con picados, sal y limón. Usar el mismo día; cubrir con film en contacto.
A6: Guacamole | B6: Tomate | C6: 0.5 | D6: lb | E6: 1 | F6: =C6*E6 -> 0.5
A7: Guacamole | B7: Cebolla | C7: 0.25 | D7: lb | E7: 0.8 | F7: =C7*E7 -> 0.2
A8: Guacamole | B8: Cilantro | C8: 0.5 | D8: manojo | E8: 0.5 | F8: =C8*E8 -> 0.25
A9: Guacamole | B9: Limón | C9: 2 | D9: unidad | E9: 0.15 | F9: =C9*E9 -> 0.3
B10: Costo de la preparación · Batch cost | F10: =SUM(F5:F9) -> 5.25
B11: Rendimiento (oz) · Yield | C11: 24 | G11: Estimado — pese su primera tanda y actualice. · Estimate — weigh first batch.
B12: Costo por oz · Cost per oz | F12: =IFERROR(F10/C11,0) -> 0.21875
A14: Pico de gallo | B14: Tomate | C14: 1 | D14: lb | E14: 1 | F14: =C14*E14 -> 1 | G14: Picar en cubos pequeños, sazonar con sal y limón. 2 días refrigerado.
A15: Pico de gallo | B15: Cebolla | C15: 0.5 | D15: lb | E15: 0.8 | F15: =C15*E15 -> 0.4
A16: Pico de gallo | B16: Cilantro | C16: 0.5 | D16: manojo | E16: 0.5 | F16: =C16*E16 -> 0.25
A17: Pico de gallo | B17: Limón | C17: 2 | D17: unidad | E17: 0.15 | F17: =C17*E17 -> 0.3
A18: Pico de gallo | B18: Jalapeño | C18: 1 | D18: unidad | E18: 0.1 | F18: =C18*E18 -> 0.1
B19: Costo de la preparación · Batch cost | F19: =SUM(F14:F18) -> 2.05
B20: Rendimiento (oz) · Yield | C20: 20 | G20: Estimado — pese su primera tanda y actualice. · Estimate — weigh first batch.
B21: Costo por oz · Cost per oz | F21: =IFERROR(F19/C20,0) -> 0.1025
A23: Cebolla caramelizada balsámica | B23: Cebolla | C23: 3 | D23: lb | E23: 0.8 | F23: =C23*E23 -> 2.4 | G23: Cocinar cebolla en mantequilla a fuego bajo 40 min, reducir con balsámico. 5 días refrigerado.
A24: Balsamic caramelized onion | B24: Mantequilla | C24: 0.25 | D24: lb | E24: 4 | F24: =C24*E24 -> 1
A25: Cebolla caramelizada balsámica | B25: Vinagre balsámico | C25: 4 | D25: oz | E25: 0.3 | F25: =C25*E25 -> 1.2
A26: Cebolla caramelizada balsámica | B26: Azúcar morena | C26: 1 | D26: oz | E26: 0.05 | F26: =C26*E26 -> 0.05
B27: Costo de la preparación · Batch cost | F27: =SUM(F23:F26) -> 4.65
B28: Rendimiento (oz) · Yield | C28: 16 | G28: Estimado — pese su primera tanda y actualice. · Estimate — weigh first batch.
B29: Costo por oz · Cost per oz | F29: =IFERROR(F27/C28,0) -> 0.290625
A31: Salsa buffalo | B31: Salsa picante tipo cayena | C31: 16 | D31: oz | E31: 0.12 | F31: =C31*E31 -> 1.92 | G31: Emulsionar salsa picante con mantequilla derretida. 7 días refrigerado; recalentar suave.
A32: Buffalo sauce | B32: Mantequilla | C32: 0.5 | D32: lb | E32: 4 | F32: =C32*E32 -> 2
B33: Costo de la preparación · Batch cost | F33: =SUM(F31:F32) -> 3.92
B34: Rendimiento (oz) · Yield | C34: 24 | G34: Estimado — pese su primera tanda y actualice. · Estimate — weigh first batch.
B35: Costo por oz · Cost per oz | F35: =IFERROR(F33/C34,0) -> 0.16333333
A37: Salsa al ajillo con vino blanco | B37: Ajo | C37: 0.25 | D37: lb | E37: 3 | F37: =C37*E37 -> 0.75 | G37: Sofreír ajo en mantequilla, desglasar con vino, reducir a la mitad, perejil al final. 3 días.
A38: Garlic white-wine sauce | B38: Mantequilla | C38: 0.5 | D38: lb | E38: 4 | F38: =C38*E38 -> 2
A39: Salsa al ajillo con vino blanco | B39: Vino blanco de cocina | C39: 8 | D39: oz | E39: 0.24 | F39: =C39*E39 -> 1.92
A40: Salsa al ajillo con vino blanco | B40: Perejil | C40: 0.5 | D40: manojo | E40: 0.5 | F40: =C40*E40 -> 0.25
B41: Costo de la preparación · Batch cost | F41: =SUM(F37:F40) -> 4.92
B42: Rendimiento (oz) · Yield | C42: 20 | G42: Estimado — pese su primera tanda y actualice. · Estimate — weigh first batch.
B43: Costo por oz · Cost per oz | F43: =IFERROR(F41/C42,0) -> 0.246
A45: Carne mechada | B45: Falda de res | C45: 5 | D45: lb | E45: 4.5 | F45: =C45*E45 -> 22.5 | G45: Cocinar la falda a presión 45 min, deshilachar y guisar con sofrito. 4 días refrigerado.
A46: Shredded beef | B46: Cebolla | C46: 1 | D46: lb | E46: 0.8 | F46: =C46*E46 -> 0.8
...

Sheet Especificaciones
A1: Líneas de receta — una fila por ingrediente (alimenta todos los costos)
A2: Recipe lines — one row per ingredient
A4: Plato | B4: Dish (EN) | C4: Ingrediente | D4: Cant. · Qty | E4: Unidad | F4: Costo / unidad | G4: Costo línea
A5: Chicharroncitos del burro | B5: Pork cracklings | C5: Panza de cerdo | D5: 0.6 | E5: =IFERROR(INDEX(Insumos!$F$5:$F$56,MATCH(C5,Insumos!$A$5:$A$56,0)),"?") -> lb | F5: =IFERROR(INDEX(Insumos!$I$5:$I$56,MATCH(C5,Insumos!$A$5:$A$56,0)),0) -> 5.8333333 | G5: =D5*F5 -> 3.5
A6: Chicharroncitos del burro | B6: Pork cracklings | C6: Guacamole | D6: 3 | E6: =IFERROR(INDEX(Insumos!$F$5:$F$56,MATCH(C6,Insumos!$A$5:$A$56,0)),"?") -> oz | F6: =IFERROR(INDEX(Insumos!$I$5:$I$56,MATCH(C6,Insumos!$A$5:$A$56,0)),0) -> 0.21875 | G6: =D6*F6 -> 0.65625
A7: Chicharroncitos del burro | B7: Pork cracklings | C7: Aceite de freír (porción) | D7: 1 | E7: =IFERROR(INDEX(Insumos!$F$5:$F$56,MATCH(C7,Insumos!$A$5:$A$56,0)),"?") -> unidad | F7: =IFERROR(INDEX(Insumos!$I$5:$I$56,MATCH(C7,Insumos!$A$5:$A$56,0)),0) -> 0.25 | G7: =D7*F7 -> 0.25
A8: Chicharroncitos del burro | B8: Pork cracklings | C8: Sazón de la casa (porción) | D8: 1 | E8: =IFERROR(INDEX(Insumos!$F$5:$F$56,MATCH(C8,Insumos!$A$5:$A$56,0)),"?") -> unidad | F8: =IFERROR(INDEX(Insumos!$I$5:$I$56,MATCH(C8,Insumos!$A$5:$A$56,0)),0) -> 0.25 | G8: =D8*F8 -> 0.25
A9: Chicharroncitos del burro | B9: Pork cracklings | C9: Condimentos y varios (por plato) | D9: 1 | E9: =IFERROR(INDEX(Insumos!$F$5:$F$56,MATCH(C9,Insumos!$A$5:$A$56,0)),"?") -> unidad | F9: =IFERROR(INDEX(Insumos!$I$5:$I$56,MATCH(C9,Insumos!$A$5:$A$56,0)),0) -> 0.2 | G9: =D9*F9 -> 0.2
A10: Mini sliders Angus (3 unid) | B10: Angus sliders (3) | C10: Carne molida Angus | D10: 0.5 | E10: =IFERROR(INDEX(Insumos!$F$5:$F$56,MATCH(C10,Insumos!$A$5:$A$56,0)),"?") -> lb | F10: =IFERROR(INDEX(Insumos!$I$5:$I$56,MATCH(C10,Insumos!$A$5:$A$56,0)),0) -> 5.8823529 | G10: =D10*F10 -> 2.9411765
A11: Mini sliders Angus (3 unid) | B11: Angus sliders (3) | C11: Mini pan de slider | D11: 3 | E11: =IFERROR(INDEX(Insumos!$F$5:$F$56,MATCH(C11,Insumos!$A$5:$A$56,0)),"?") -> unidad | F11: =IFERROR(INDEX(Insumos!$I$5:$I$56,MATCH(C11,Insumos!$A$5:$A$56,0)),0) -> 0.25 | G11: =D11*F11 -> 0.75
A12: Mini sliders Angus (3 unid) | B12: Angus sliders (3) | C12: Queso en lámina (prensado) | D12: 3 | E12: =IFERROR(INDEX(Insumos!$F$5:$F$56,MATCH(C12,Insumos!$A$5:$A$56,0)),"?") -> unidad | F12: =IFERROR(INDEX(Insumos!$I$5:$I$56,MATCH(C12,Insumos!$A$5:$A$56,0)),0) -> 0.2 | G12: =D12*F12 -> 0.6
A13: Mini sliders Angus (3 unid) | B13: Angus sliders (3) | C13: Condimentos y varios (por plato) | D13: 1 | E13: =IFERROR(INDEX(Insumos!$F$5:$F$56,MATCH(C13,Insumos!$A$5:$A$56,0)),"?") -> unidad | F13: =IFERROR(INDEX(Insumos!$I$5:$I$56,MATCH(C13,Insumos!$A$5:$A$56,0)),0) -> 0.2 | G13: =D13*F13 -> 0.2
A14: Nachos de carne | B14: Beef nachos | C14: Tortilla de maíz | D14: 8 | E14: =IFERROR(INDEX(Insumos!$F$5:$F$56,MATCH(C14,Insumos!$A$5:$A$56,0)),"?") -> unidad | F14: =IFERROR(INDEX(Insumos!$I$5:$I$56,MATCH(C14,Insumos!$A$5:$A$56,0)),0) -> 0.1 | G14: =D14*F14 -> 0.8
A15: Nachos de carne | B15: Beef nachos | C15: Aceite de freír (porción) | D15: 1 | E15: =IFERROR(INDEX(Insumos!$F$5:$F$56,MATCH(C15,Insumos!$A$5:$A$56,0)),"?") -> unidad | F15: =IFERROR(INDEX(Insumos!$I$5:$I$56,MATCH(C15,Insumos!$A$5:$A$56,0)),0) -> 0.25 | G15: =D15*F15 -> 0.25
A16: Nachos de carne | B16: Beef nachos | C16: Carne molida de res | D16: 0.3 | E16: =IFERROR(INDEX(Insumos!$F$5:$F$56,MATCH(C16,Insumos!$A$5:$A$56,0)),"?") -> lb | F16: =IFERROR(INDEX(Insumos!$I$5:$I$56,MATCH(C16,Insumos!$A$5:$A$56,0)),0) -> 5.625 | G16: =D16*F16 -> 1.6875
... A109: Totopos | B109: Tortilla chips | C109: Aceite de freír (porción) | D109: 1 | E109: =IFERROR(INDEX(Insumos!$F$5:$F$56,MATCH(C109,Insumos!$A$5:$A$56,0)),"?") -> unidad | F109: =IFERROR(INDEX(Insumos!$I$5:$I$56,MATCH(C109,Insumos!$A$5:$A$56,0)),0) -> 0.25 | G109: =D109*F109 -> 0.25
